2022-01-05 21:18:57,978 INFO    MainThread:35296 [internal.py:wandb_internal():90] W&B internal server running at pid: 35296, started at: 2022-01-05 21:18:57.978414
2022-01-05 21:18:57,981 INFO    WriterThread:35296 [datastore.py:open_for_write():77] open: D:\GitHub\OnePunch\OnepunchPrompt_for_new_transformers\wandb\run-20220105_211856-3if0dwkg\run-3if0dwkg.wandb
2022-01-05 21:18:57,982 DEBUG   HandlerThread:35296 [handler.py:handle_request():130] handle_request: check_version
2022-01-05 21:18:57,985 DEBUG   SenderThread:35296 [sender.py:send():234] send: header
2022-01-05 21:18:57,985 DEBUG   SenderThread:35296 [sender.py:send_request():248] send_request: check_version
2022-01-05 21:18:58,006 DEBUG   SenderThread:35296 [sender.py:send():234] send: run
2022-01-05 21:19:01,390 ERROR   SenderThread:35296 [retry.py:__call__():126] Retry attempt failed:
Traceback (most recent call last):
  File "D:\anaconda\envs\myprompt\lib\site-packages\urllib3\connectionpool.py", line 696, in urlopen
    self._prepare_proxy(conn)
  File "D:\anaconda\envs\myprompt\lib\site-packages\urllib3\connectionpool.py", line 964, in _prepare_proxy
    conn.connect()
  File "D:\anaconda\envs\myprompt\lib\site-packages\urllib3\connection.py", line 364, in connect
    conn = self._connect_tls_proxy(hostname, conn)
  File "D:\anaconda\envs\myprompt\lib\site-packages\urllib3\connection.py", line 507, in _connect_tls_proxy
    ssl_context=ssl_context,
  File "D:\anaconda\envs\myprompt\lib\site-packages\urllib3\util\ssl_.py", line 453, in ssl_wrap_socket
    ssl_sock = _ssl_wrap_socket_impl(sock, context, tls_in_tls)
  File "D:\anaconda\envs\myprompt\lib\site-packages\urllib3\util\ssl_.py", line 495, in _ssl_wrap_socket_impl
    return ssl_context.wrap_socket(sock)
  File "D:\anaconda\envs\myprompt\lib\ssl.py", line 423, in wrap_socket
    session=session
  File "D:\anaconda\envs\myprompt\lib\ssl.py", line 870, in _create
    self.do_handshake()
  File "D:\anaconda\envs\myprompt\lib\ssl.py", line 1139, in do_handshake
    self._sslobj.do_handshake()
OSError: [Errno 0] Error

During handling of the above exception, another exception occurred:

Traceback (most recent call last):
  File "D:\anaconda\envs\myprompt\lib\site-packages\requests\adapters.py", line 449, in send
    timeout=timeout
  File "D:\anaconda\envs\myprompt\lib\site-packages\urllib3\connectionpool.py", line 756, in urlopen
    method, url, error=e, _pool=self, _stacktrace=sys.exc_info()[2]
  File "D:\anaconda\envs\myprompt\lib\site-packages\urllib3\util\retry.py", line 574, in increment
    raise MaxRetryError(_pool, url, error or ResponseError(cause))
urllib3.exceptions.MaxRetryError: HTTPSConnectionPool(host='api.wandb.ai', port=443): Max retries exceeded with url: /graphql (Caused by ProxyError('Cannot connect to proxy.', OSError(0, 'Error')))

During handling of the above exception, another exception occurred:

Traceback (most recent call last):
  File "D:\anaconda\envs\myprompt\lib\site-packages\wandb\sdk\lib\retry.py", line 102, in __call__
    result = self._call_fn(*args, **kwargs)
  File "D:\anaconda\envs\myprompt\lib\site-packages\wandb\sdk\internal\internal_api.py", line 141, in execute
    return self.client.execute(*args, **kwargs)
  File "D:\anaconda\envs\myprompt\lib\site-packages\wandb\vendor\gql-0.2.0\gql\client.py", line 52, in execute
    result = self._get_result(document, *args, **kwargs)
  File "D:\anaconda\envs\myprompt\lib\site-packages\wandb\vendor\gql-0.2.0\gql\client.py", line 60, in _get_result
    return self.transport.execute(document, *args, **kwargs)
  File "D:\anaconda\envs\myprompt\lib\site-packages\wandb\vendor\gql-0.2.0\gql\transport\requests.py", line 38, in execute
    request = requests.post(self.url, **post_args)
  File "D:\anaconda\envs\myprompt\lib\site-packages\requests\api.py", line 117, in post
    return request('post', url, data=data, json=json, **kwargs)
  File "D:\anaconda\envs\myprompt\lib\site-packages\requests\api.py", line 61, in request
    return session.request(method=method, url=url, **kwargs)
  File "D:\anaconda\envs\myprompt\lib\site-packages\requests\sessions.py", line 542, in request
    resp = self.send(prep, **send_kwargs)
  File "D:\anaconda\envs\myprompt\lib\site-packages\requests\sessions.py", line 655, in send
    r = adapter.send(request, **kwargs)
  File "D:\anaconda\envs\myprompt\lib\site-packages\requests\adapters.py", line 510, in send
    raise ProxyError(e, request=request)
requests.exceptions.ProxyError: HTTPSConnectionPool(host='api.wandb.ai', port=443): Max retries exceeded with url: /graphql (Caused by ProxyError('Cannot connect to proxy.', OSError(0, 'Error')))
2022-01-05 21:19:28,008 DEBUG   HandlerThread:35296 [handler.py:handle_request():130] handle_request: shutdown
2022-01-05 21:19:28,008 INFO    HandlerThread:35296 [handler.py:finish():731] shutting down handler
2022-01-05 21:19:28,020 INFO    WriterThread:35296 [datastore.py:close():281] close: D:\GitHub\OnePunch\OnepunchPrompt_for_new_transformers\wandb\run-20220105_211856-3if0dwkg\run-3if0dwkg.wandb
2022-01-05 21:19:34,381 INFO    SenderThread:35296 [dir_watcher.py:__init__():169] watching files in: D:\GitHub\OnePunch\OnepunchPrompt_for_new_transformers\wandb\run-20220105_211856-3if0dwkg\files
2022-01-05 21:19:34,381 INFO    SenderThread:35296 [sender.py:_start_run_threads():807] run started: 3if0dwkg with start time 1641388736
2022-01-05 21:19:34,381 INFO    SenderThread:35296 [sender.py:finish():1070] shutting down sender
2022-01-05 21:19:34,381 INFO    SenderThread:35296 [dir_watcher.py:finish():283] shutting down directory watcher
2022-01-05 21:19:35,381 INFO    SenderThread:35296 [dir_watcher.py:finish():313] scan: D:\GitHub\OnePunch\OnepunchPrompt_for_new_transformers\wandb\run-20220105_211856-3if0dwkg\files
2022-01-05 21:19:35,382 INFO    SenderThread:35296 [dir_watcher.py:finish():327] scan save: D:\GitHub\OnePunch\OnepunchPrompt_for_new_transformers\wandb\run-20220105_211856-3if0dwkg\files\config.yaml config.yaml
2022-01-05 21:19:35,382 INFO    SenderThread:35296 [file_pusher.py:finish():177] shutting down file pusher
2022-01-05 21:19:35,382 INFO    SenderThread:35296 [file_pusher.py:join():182] waiting for file pusher
2022-01-05 21:19:36,459 INFO    Thread-14 :35296 [upload_job.py:push():137] Uploaded file D:\GitHub\OnePunch\OnepunchPrompt_for_new_transformers\wandb\run-20220105_211856-3if0dwkg\files\config.yaml
2022-01-05 21:19:37,299 INFO    MainThread:35296 [internal.py:handle_exit():77] Internal process exited
