2022-01-05 21:09:14 ERROR Retry attempt failed:
Traceback (most recent call last):
  File "D:\anaconda\envs\myprompt\lib\site-packages\urllib3\connectionpool.py", line 696, in urlopen
    self._prepare_proxy(conn)
  File "D:\anaconda\envs\myprompt\lib\site-packages\urllib3\connectionpool.py", line 964, in _prepare_proxy
    conn.connect()
  File "D:\anaconda\envs\myprompt\lib\site-packages\urllib3\connection.py", line 364, in connect
    conn = self._connect_tls_proxy(hostname, conn)
  File "D:\anaconda\envs\myprompt\lib\site-packages\urllib3\connection.py", line 507, in _connect_tls_proxy
    ssl_context=ssl_context,
  File "D:\anaconda\envs\myprompt\lib\site-packages\urllib3\util\ssl_.py", line 453, in ssl_wrap_socket
    ssl_sock = _ssl_wrap_socket_impl(sock, context, tls_in_tls)
  File "D:\anaconda\envs\myprompt\lib\site-packages\urllib3\util\ssl_.py", line 495, in _ssl_wrap_socket_impl
    return ssl_context.wrap_socket(sock)
  File "D:\anaconda\envs\myprompt\lib\ssl.py", line 423, in wrap_socket
    session=session
  File "D:\anaconda\envs\myprompt\lib\ssl.py", line 870, in _create
    self.do_handshake()
  File "D:\anaconda\envs\myprompt\lib\ssl.py", line 1139, in do_handshake
    self._sslobj.do_handshake()
OSError: [Errno 0] Error

During handling of the above exception, another exception occurred:

Traceback (most recent call last):
  File "D:\anaconda\envs\myprompt\lib\site-packages\requests\adapters.py", line 449, in send
    timeout=timeout
  File "D:\anaconda\envs\myprompt\lib\site-packages\urllib3\connectionpool.py", line 756, in urlopen
    method, url, error=e, _pool=self, _stacktrace=sys.exc_info()[2]
  File "D:\anaconda\envs\myprompt\lib\site-packages\urllib3\util\retry.py", line 574, in increment
    raise MaxRetryError(_pool, url, error or ResponseError(cause))
urllib3.exceptions.MaxRetryError: HTTPSConnectionPool(host='api.wandb.ai', port=443): Max retries exceeded with url: /graphql (Caused by ProxyError('Cannot connect to proxy.', OSError(0, 'Error')))

During handling of the above exception, another exception occurred:

Traceback (most recent call last):
  File "D:\anaconda\envs\myprompt\lib\site-packages\wandb\sdk\lib\retry.py", line 102, in __call__
    result = self._call_fn(*args, **kwargs)
  File "D:\anaconda\envs\myprompt\lib\site-packages\wandb\sdk\internal\internal_api.py", line 141, in execute
    return self.client.execute(*args, **kwargs)
  File "D:\anaconda\envs\myprompt\lib\site-packages\wandb\vendor\gql-0.2.0\gql\client.py", line 52, in execute
    result = self._get_result(document, *args, **kwargs)
  File "D:\anaconda\envs\myprompt\lib\site-packages\wandb\vendor\gql-0.2.0\gql\client.py", line 60, in _get_result
    return self.transport.execute(document, *args, **kwargs)
  File "D:\anaconda\envs\myprompt\lib\site-packages\wandb\vendor\gql-0.2.0\gql\transport\requests.py", line 38, in execute
    request = requests.post(self.url, **post_args)
  File "D:\anaconda\envs\myprompt\lib\site-packages\requests\api.py", line 117, in post
    return request('post', url, data=data, json=json, **kwargs)
  File "D:\anaconda\envs\myprompt\lib\site-packages\requests\api.py", line 61, in request
    return session.request(method=method, url=url, **kwargs)
  File "D:\anaconda\envs\myprompt\lib\site-packages\requests\sessions.py", line 542, in request
    resp = self.send(prep, **send_kwargs)
  File "D:\anaconda\envs\myprompt\lib\site-packages\requests\sessions.py", line 655, in send
    r = adapter.send(request, **kwargs)
  File "D:\anaconda\envs\myprompt\lib\site-packages\requests\adapters.py", line 510, in send
    raise ProxyError(e, request=request)
requests.exceptions.ProxyError: HTTPSConnectionPool(host='api.wandb.ai', port=443): Max retries exceeded with url: /graphql (Caused by ProxyError('Cannot connect to proxy.', OSError(0, 'Error')))
2022-01-05 21:18:33 ERROR Retry attempt failed:
Traceback (most recent call last):
  File "D:\anaconda\envs\myprompt\lib\site-packages\urllib3\connectionpool.py", line 696, in urlopen
    self._prepare_proxy(conn)
  File "D:\anaconda\envs\myprompt\lib\site-packages\urllib3\connectionpool.py", line 964, in _prepare_proxy
    conn.connect()
  File "D:\anaconda\envs\myprompt\lib\site-packages\urllib3\connection.py", line 364, in connect
    conn = self._connect_tls_proxy(hostname, conn)
  File "D:\anaconda\envs\myprompt\lib\site-packages\urllib3\connection.py", line 507, in _connect_tls_proxy
    ssl_context=ssl_context,
  File "D:\anaconda\envs\myprompt\lib\site-packages\urllib3\util\ssl_.py", line 453, in ssl_wrap_socket
    ssl_sock = _ssl_wrap_socket_impl(sock, context, tls_in_tls)
  File "D:\anaconda\envs\myprompt\lib\site-packages\urllib3\util\ssl_.py", line 495, in _ssl_wrap_socket_impl
    return ssl_context.wrap_socket(sock)
  File "D:\anaconda\envs\myprompt\lib\ssl.py", line 423, in wrap_socket
    session=session
  File "D:\anaconda\envs\myprompt\lib\ssl.py", line 870, in _create
    self.do_handshake()
  File "D:\anaconda\envs\myprompt\lib\ssl.py", line 1139, in do_handshake
    self._sslobj.do_handshake()
OSError: [Errno 0] Error

During handling of the above exception, another exception occurred:

Traceback (most recent call last):
  File "D:\anaconda\envs\myprompt\lib\site-packages\requests\adapters.py", line 449, in send
    timeout=timeout
  File "D:\anaconda\envs\myprompt\lib\site-packages\urllib3\connectionpool.py", line 756, in urlopen
    method, url, error=e, _pool=self, _stacktrace=sys.exc_info()[2]
  File "D:\anaconda\envs\myprompt\lib\site-packages\urllib3\util\retry.py", line 574, in increment
    raise MaxRetryError(_pool, url, error or ResponseError(cause))
urllib3.exceptions.MaxRetryError: HTTPSConnectionPool(host='api.wandb.ai', port=443): Max retries exceeded with url: /graphql (Caused by ProxyError('Cannot connect to proxy.', OSError(0, 'Error')))

During handling of the above exception, another exception occurred:

Traceback (most recent call last):
  File "D:\anaconda\envs\myprompt\lib\site-packages\wandb\sdk\lib\retry.py", line 102, in __call__
    result = self._call_fn(*args, **kwargs)
  File "D:\anaconda\envs\myprompt\lib\site-packages\wandb\sdk\internal\internal_api.py", line 141, in execute
    return self.client.execute(*args, **kwargs)
  File "D:\anaconda\envs\myprompt\lib\site-packages\wandb\vendor\gql-0.2.0\gql\client.py", line 52, in execute
    result = self._get_result(document, *args, **kwargs)
  File "D:\anaconda\envs\myprompt\lib\site-packages\wandb\vendor\gql-0.2.0\gql\client.py", line 60, in _get_result
    return self.transport.execute(document, *args, **kwargs)
  File "D:\anaconda\envs\myprompt\lib\site-packages\wandb\vendor\gql-0.2.0\gql\transport\requests.py", line 38, in execute
    request = requests.post(self.url, **post_args)
  File "D:\anaconda\envs\myprompt\lib\site-packages\requests\api.py", line 117, in post
    return request('post', url, data=data, json=json, **kwargs)
  File "D:\anaconda\envs\myprompt\lib\site-packages\requests\api.py", line 61, in request
    return session.request(method=method, url=url, **kwargs)
  File "D:\anaconda\envs\myprompt\lib\site-packages\requests\sessions.py", line 542, in request
    resp = self.send(prep, **send_kwargs)
  File "D:\anaconda\envs\myprompt\lib\site-packages\requests\sessions.py", line 655, in send
    r = adapter.send(request, **kwargs)
  File "D:\anaconda\envs\myprompt\lib\site-packages\requests\adapters.py", line 510, in send
    raise ProxyError(e, request=request)
requests.exceptions.ProxyError: HTTPSConnectionPool(host='api.wandb.ai', port=443): Max retries exceeded with url: /graphql (Caused by ProxyError('Cannot connect to proxy.', OSError(0, 'Error')))
2022-01-05 21:26:15 ERROR Retry attempt failed:
Traceback (most recent call last):
  File "D:\anaconda\envs\myprompt\lib\site-packages\urllib3\connectionpool.py", line 696, in urlopen
    self._prepare_proxy(conn)
  File "D:\anaconda\envs\myprompt\lib\site-packages\urllib3\connectionpool.py", line 964, in _prepare_proxy
    conn.connect()
  File "D:\anaconda\envs\myprompt\lib\site-packages\urllib3\connection.py", line 364, in connect
    conn = self._connect_tls_proxy(hostname, conn)
  File "D:\anaconda\envs\myprompt\lib\site-packages\urllib3\connection.py", line 507, in _connect_tls_proxy
    ssl_context=ssl_context,
  File "D:\anaconda\envs\myprompt\lib\site-packages\urllib3\util\ssl_.py", line 453, in ssl_wrap_socket
    ssl_sock = _ssl_wrap_socket_impl(sock, context, tls_in_tls)
  File "D:\anaconda\envs\myprompt\lib\site-packages\urllib3\util\ssl_.py", line 495, in _ssl_wrap_socket_impl
    return ssl_context.wrap_socket(sock)
  File "D:\anaconda\envs\myprompt\lib\ssl.py", line 423, in wrap_socket
    session=session
  File "D:\anaconda\envs\myprompt\lib\ssl.py", line 870, in _create
    self.do_handshake()
  File "D:\anaconda\envs\myprompt\lib\ssl.py", line 1139, in do_handshake
    self._sslobj.do_handshake()
OSError: [Errno 0] Error

During handling of the above exception, another exception occurred:

Traceback (most recent call last):
  File "D:\anaconda\envs\myprompt\lib\site-packages\requests\adapters.py", line 449, in send
    timeout=timeout
  File "D:\anaconda\envs\myprompt\lib\site-packages\urllib3\connectionpool.py", line 756, in urlopen
    method, url, error=e, _pool=self, _stacktrace=sys.exc_info()[2]
  File "D:\anaconda\envs\myprompt\lib\site-packages\urllib3\util\retry.py", line 574, in increment
    raise MaxRetryError(_pool, url, error or ResponseError(cause))
urllib3.exceptions.MaxRetryError: HTTPSConnectionPool(host='api.wandb.ai', port=443): Max retries exceeded with url: /graphql (Caused by ProxyError('Cannot connect to proxy.', OSError(0, 'Error')))

During handling of the above exception, another exception occurred:

Traceback (most recent call last):
  File "D:\anaconda\envs\myprompt\lib\site-packages\wandb\sdk\lib\retry.py", line 102, in __call__
    result = self._call_fn(*args, **kwargs)
  File "D:\anaconda\envs\myprompt\lib\site-packages\wandb\sdk\internal\internal_api.py", line 141, in execute
    return self.client.execute(*args, **kwargs)
  File "D:\anaconda\envs\myprompt\lib\site-packages\wandb\vendor\gql-0.2.0\gql\client.py", line 52, in execute
    result = self._get_result(document, *args, **kwargs)
  File "D:\anaconda\envs\myprompt\lib\site-packages\wandb\vendor\gql-0.2.0\gql\client.py", line 60, in _get_result
    return self.transport.execute(document, *args, **kwargs)
  File "D:\anaconda\envs\myprompt\lib\site-packages\wandb\vendor\gql-0.2.0\gql\transport\requests.py", line 38, in execute
    request = requests.post(self.url, **post_args)
  File "D:\anaconda\envs\myprompt\lib\site-packages\requests\api.py", line 117, in post
    return request('post', url, data=data, json=json, **kwargs)
  File "D:\anaconda\envs\myprompt\lib\site-packages\requests\api.py", line 61, in request
    return session.request(method=method, url=url, **kwargs)
  File "D:\anaconda\envs\myprompt\lib\site-packages\requests\sessions.py", line 542, in request
    resp = self.send(prep, **send_kwargs)
  File "D:\anaconda\envs\myprompt\lib\site-packages\requests\sessions.py", line 655, in send
    r = adapter.send(request, **kwargs)
  File "D:\anaconda\envs\myprompt\lib\site-packages\requests\adapters.py", line 510, in send
    raise ProxyError(e, request=request)
requests.exceptions.ProxyError: HTTPSConnectionPool(host='api.wandb.ai', port=443): Max retries exceeded with url: /graphql (Caused by ProxyError('Cannot connect to proxy.', OSError(0, 'Error')))
