2022-01-05 21:05:41,693 INFO    MainThread:34124 [internal.py:wandb_internal():90] W&B internal server running at pid: 34124, started at: 2022-01-05 21:05:41.693035
2022-01-05 21:05:41,696 INFO    WriterThread:34124 [datastore.py:open_for_write():77] open: D:\GitHub\OnePunch\OnepunchPrompt_for_new_transformers\wandb\run-20220105_210540-vpr2dq9c\run-vpr2dq9c.wandb
2022-01-05 21:05:41,696 DEBUG   HandlerThread:34124 [handler.py:handle_request():130] handle_request: check_version
2022-01-05 21:05:41,698 DEBUG   SenderThread:34124 [sender.py:send():234] send: header
2022-01-05 21:05:41,699 DEBUG   SenderThread:34124 [sender.py:send_request():248] send_request: check_version
2022-01-05 21:05:41,881 DEBUG   SenderThread:34124 [sender.py:send():234] send: run
2022-01-05 21:05:41,903 DEBUG   SenderThread:34124 [git.py:repo():33] git repository is invalid
2022-01-05 21:05:42,255 ERROR   SenderThread:34124 [internal_api.py:execute():144] 404 response executing GraphQL.
2022-01-05 21:05:42,255 ERROR   SenderThread:34124 [internal_api.py:execute():145] {"errors":[{"message":"entity Shuailong Zhu not found during upsertBucket","path":["upsertBucket"]}],"data":{"upsertBucket":null}}
2022-01-05 21:05:42,881 INFO    WriterThread:34124 [datastore.py:close():281] close: D:\GitHub\OnePunch\OnepunchPrompt_for_new_transformers\wandb\run-20220105_210540-vpr2dq9c\run-vpr2dq9c.wandb
2022-01-05 21:05:42,881 INFO    HandlerThread:34124 [handler.py:finish():731] shutting down handler
2022-01-05 21:05:42,881 ERROR   MainThread:34124 [internal.py:wandb_internal():158] Thread SenderThread:
Traceback (most recent call last):
  File "D:\anaconda\envs\myprompt\lib\site-packages\wandb\sdk\lib\retry.py", line 102, in __call__
    result = self._call_fn(*args, **kwargs)
  File "D:\anaconda\envs\myprompt\lib\site-packages\wandb\sdk\internal\internal_api.py", line 147, in execute
    six.reraise(*sys.exc_info())
  File "D:\anaconda\envs\myprompt\lib\site-packages\six.py", line 719, in reraise
    raise value
  File "D:\anaconda\envs\myprompt\lib\site-packages\wandb\sdk\internal\internal_api.py", line 141, in execute
    return self.client.execute(*args, **kwargs)
  File "D:\anaconda\envs\myprompt\lib\site-packages\wandb\vendor\gql-0.2.0\gql\client.py", line 52, in execute
    result = self._get_result(document, *args, **kwargs)
  File "D:\anaconda\envs\myprompt\lib\site-packages\wandb\vendor\gql-0.2.0\gql\client.py", line 60, in _get_result
    return self.transport.execute(document, *args, **kwargs)
  File "D:\anaconda\envs\myprompt\lib\site-packages\wandb\vendor\gql-0.2.0\gql\transport\requests.py", line 39, in execute
    request.raise_for_status()
  File "D:\anaconda\envs\myprompt\lib\site-packages\requests\models.py", line 953, in raise_for_status
    raise HTTPError(http_error_msg, response=self)
requests.exceptions.HTTPError: 404 Client Error: Not Found for url: https://api.wandb.ai/graphql

During handling of the above exception, another exception occurred:

Traceback (most recent call last):
  File "D:\anaconda\envs\myprompt\lib\site-packages\wandb\apis\normalize.py", line 24, in wrapper
    return func(*args, **kwargs)
  File "D:\anaconda\envs\myprompt\lib\site-packages\wandb\sdk\internal\internal_api.py", line 1298, in upsert_run
    response = self.gql(mutation, variable_values=variable_values, **kwargs)
  File "D:\anaconda\envs\myprompt\lib\site-packages\wandb\sdk\lib\retry.py", line 118, in __call__
    if not check_retry_fn(e):
  File "D:\anaconda\envs\myprompt\lib\site-packages\wandb\util.py", line 821, in no_retry_auth
    raise CommError("Permission denied, ask the project owner to grant you access")
wandb.errors.CommError: Permission denied, ask the project owner to grant you access

During handling of the above exception, another exception occurred:

Traceback (most recent call last):
  File "D:\anaconda\envs\myprompt\lib\site-packages\wandb\sdk\internal\internal_util.py", line 52, in run
    self._run()
  File "D:\anaconda\envs\myprompt\lib\site-packages\wandb\sdk\internal\internal_util.py", line 102, in _run
    self._process(record)
  File "D:\anaconda\envs\myprompt\lib\site-packages\wandb\sdk\internal\internal.py", line 291, in _process
    self._sm.send(record)
  File "D:\anaconda\envs\myprompt\lib\site-packages\wandb\sdk\internal\sender.py", line 236, in send
    send_handler(record)
  File "D:\anaconda\envs\myprompt\lib\site-packages\wandb\sdk\internal\sender.py", line 687, in send_run
    self._init_run(run, config_value_dict)
  File "D:\anaconda\envs\myprompt\lib\site-packages\wandb\sdk\internal\sender.py", line 725, in _init_run
    commit=run.git.last_commit or None,
  File "D:\anaconda\envs\myprompt\lib\site-packages\wandb\apis\normalize.py", line 62, in wrapper
    six.reraise(CommError, CommError(message, err), sys.exc_info()[2])
  File "D:\anaconda\envs\myprompt\lib\site-packages\six.py", line 718, in reraise
    raise value.with_traceback(tb)
  File "D:\anaconda\envs\myprompt\lib\site-packages\wandb\apis\normalize.py", line 24, in wrapper
    return func(*args, **kwargs)
  File "D:\anaconda\envs\myprompt\lib\site-packages\wandb\sdk\internal\internal_api.py", line 1298, in upsert_run
    response = self.gql(mutation, variable_values=variable_values, **kwargs)
  File "D:\anaconda\envs\myprompt\lib\site-packages\wandb\sdk\lib\retry.py", line 118, in __call__
    if not check_retry_fn(e):
  File "D:\anaconda\envs\myprompt\lib\site-packages\wandb\util.py", line 821, in no_retry_auth
    raise CommError("Permission denied, ask the project owner to grant you access")
wandb.errors.CommError: Permission denied, ask the project owner to grant you access
2022-01-05 21:05:44,899 INFO    MainThread:34124 [internal.py:handle_exit():77] Internal process exited
