2022-01-05 20:59:00,611 INFO    MainThread:33796 [internal.py:wandb_internal():90] W&B internal server running at pid: 33796, started at: 2022-01-05 20:59:00.611816
2022-01-05 20:59:00,615 INFO    WriterThread:33796 [datastore.py:open_for_write():77] open: D:\GitHub\OnePunch\OnepunchPrompt_for_new_transformers\wandb\run-20220105_205858-12auxwpx\run-12auxwpx.wandb
2022-01-05 20:59:00,615 DEBUG   HandlerThread:33796 [handler.py:handle_request():130] handle_request: check_version
2022-01-05 20:59:00,619 DEBUG   SenderThread:33796 [sender.py:send():234] send: header
2022-01-05 20:59:00,620 DEBUG   SenderThread:33796 [sender.py:send_request():248] send_request: check_version
2022-01-05 20:59:00,657 DEBUG   SenderThread:33796 [sender.py:send():234] send: run
2022-01-05 20:59:04,418 ERROR   SenderThread:33796 [retry.py:__call__():126] Retry attempt failed:
Traceback (most recent call last):
  File "D:\anaconda\envs\myprompt\lib\site-packages\urllib3\connectionpool.py", line 696, in urlopen
    self._prepare_proxy(conn)
  File "D:\anaconda\envs\myprompt\lib\site-packages\urllib3\connectionpool.py", line 964, in _prepare_proxy
    conn.connect()
  File "D:\anaconda\envs\myprompt\lib\site-packages\urllib3\connection.py", line 364, in connect
    conn = self._connect_tls_proxy(hostname, conn)
  File "D:\anaconda\envs\myprompt\lib\site-packages\urllib3\connection.py", line 507, in _connect_tls_proxy
    ssl_context=ssl_context,
  File "D:\anaconda\envs\myprompt\lib\site-packages\urllib3\util\ssl_.py", line 453, in ssl_wrap_socket
    ssl_sock = _ssl_wrap_socket_impl(sock, context, tls_in_tls)
  File "D:\anaconda\envs\myprompt\lib\site-packages\urllib3\util\ssl_.py", line 495, in _ssl_wrap_socket_impl
    return ssl_context.wrap_socket(sock)
  File "D:\anaconda\envs\myprompt\lib\ssl.py", line 423, in wrap_socket
    session=session
  File "D:\anaconda\envs\myprompt\lib\ssl.py", line 870, in _create
    self.do_handshake()
  File "D:\anaconda\envs\myprompt\lib\ssl.py", line 1139, in do_handshake
    self._sslobj.do_handshake()
OSError: [Errno 0] Error

During handling of the above exception, another exception occurred:

Traceback (most recent call last):
  File "D:\anaconda\envs\myprompt\lib\site-packages\requests\adapters.py", line 449, in send
    timeout=timeout
  File "D:\anaconda\envs\myprompt\lib\site-packages\urllib3\connectionpool.py", line 756, in urlopen
    method, url, error=e, _pool=self, _stacktrace=sys.exc_info()[2]
  File "D:\anaconda\envs\myprompt\lib\site-packages\urllib3\util\retry.py", line 574, in increment
    raise MaxRetryError(_pool, url, error or ResponseError(cause))
urllib3.exceptions.MaxRetryError: HTTPSConnectionPool(host='api.wandb.ai', port=443): Max retries exceeded with url: /graphql (Caused by ProxyError('Cannot connect to proxy.', OSError(0, 'Error')))

During handling of the above exception, another exception occurred:

Traceback (most recent call last):
  File "D:\anaconda\envs\myprompt\lib\site-packages\wandb\sdk\lib\retry.py", line 102, in __call__
    result = self._call_fn(*args, **kwargs)
  File "D:\anaconda\envs\myprompt\lib\site-packages\wandb\sdk\internal\internal_api.py", line 141, in execute
    return self.client.execute(*args, **kwargs)
  File "D:\anaconda\envs\myprompt\lib\site-packages\wandb\vendor\gql-0.2.0\gql\client.py", line 52, in execute
    result = self._get_result(document, *args, **kwargs)
  File "D:\anaconda\envs\myprompt\lib\site-packages\wandb\vendor\gql-0.2.0\gql\client.py", line 60, in _get_result
    return self.transport.execute(document, *args, **kwargs)
  File "D:\anaconda\envs\myprompt\lib\site-packages\wandb\vendor\gql-0.2.0\gql\transport\requests.py", line 38, in execute
    request = requests.post(self.url, **post_args)
  File "D:\anaconda\envs\myprompt\lib\site-packages\requests\api.py", line 117, in post
    return request('post', url, data=data, json=json, **kwargs)
  File "D:\anaconda\envs\myprompt\lib\site-packages\requests\api.py", line 61, in request
    return session.request(method=method, url=url, **kwargs)
  File "D:\anaconda\envs\myprompt\lib\site-packages\requests\sessions.py", line 542, in request
    resp = self.send(prep, **send_kwargs)
  File "D:\anaconda\envs\myprompt\lib\site-packages\requests\sessions.py", line 655, in send
    r = adapter.send(request, **kwargs)
  File "D:\anaconda\envs\myprompt\lib\site-packages\requests\adapters.py", line 510, in send
    raise ProxyError(e, request=request)
requests.exceptions.ProxyError: HTTPSConnectionPool(host='api.wandb.ai', port=443): Max retries exceeded with url: /graphql (Caused by ProxyError('Cannot connect to proxy.', OSError(0, 'Error')))
2022-01-05 20:59:17,402 ERROR   SenderThread:33796 [internal_api.py:execute():144] 404 response executing GraphQL.
2022-01-05 20:59:17,402 ERROR   SenderThread:33796 [internal_api.py:execute():145] {"errors":[{"message":"entity shuailong zhu not found during upsertBucket","path":["upsertBucket"]}],"data":{"upsertBucket":null}}
2022-01-05 20:59:17,666 INFO    WriterThread:33796 [datastore.py:close():281] close: D:\GitHub\OnePunch\OnepunchPrompt_for_new_transformers\wandb\run-20220105_205858-12auxwpx\run-12auxwpx.wandb
2022-01-05 20:59:17,666 INFO    HandlerThread:33796 [handler.py:finish():731] shutting down handler
2022-01-05 20:59:17,667 ERROR   MainThread:33796 [internal.py:wandb_internal():158] Thread SenderThread:
Traceback (most recent call last):
  File "D:\anaconda\envs\myprompt\lib\site-packages\wandb\sdk\lib\retry.py", line 102, in __call__
    result = self._call_fn(*args, **kwargs)
  File "D:\anaconda\envs\myprompt\lib\site-packages\wandb\sdk\internal\internal_api.py", line 147, in execute
    six.reraise(*sys.exc_info())
  File "D:\anaconda\envs\myprompt\lib\site-packages\six.py", line 719, in reraise
    raise value
  File "D:\anaconda\envs\myprompt\lib\site-packages\wandb\sdk\internal\internal_api.py", line 141, in execute
    return self.client.execute(*args, **kwargs)
  File "D:\anaconda\envs\myprompt\lib\site-packages\wandb\vendor\gql-0.2.0\gql\client.py", line 52, in execute
    result = self._get_result(document, *args, **kwargs)
  File "D:\anaconda\envs\myprompt\lib\site-packages\wandb\vendor\gql-0.2.0\gql\client.py", line 60, in _get_result
    return self.transport.execute(document, *args, **kwargs)
  File "D:\anaconda\envs\myprompt\lib\site-packages\wandb\vendor\gql-0.2.0\gql\transport\requests.py", line 39, in execute
    request.raise_for_status()
  File "D:\anaconda\envs\myprompt\lib\site-packages\requests\models.py", line 953, in raise_for_status
    raise HTTPError(http_error_msg, response=self)
requests.exceptions.HTTPError: 404 Client Error: Not Found for url: https://api.wandb.ai/graphql

During handling of the above exception, another exception occurred:

Traceback (most recent call last):
  File "D:\anaconda\envs\myprompt\lib\site-packages\wandb\apis\normalize.py", line 24, in wrapper
    return func(*args, **kwargs)
  File "D:\anaconda\envs\myprompt\lib\site-packages\wandb\sdk\internal\internal_api.py", line 1298, in upsert_run
    response = self.gql(mutation, variable_values=variable_values, **kwargs)
  File "D:\anaconda\envs\myprompt\lib\site-packages\wandb\sdk\lib\retry.py", line 118, in __call__
    if not check_retry_fn(e):
  File "D:\anaconda\envs\myprompt\lib\site-packages\wandb\util.py", line 821, in no_retry_auth
    raise CommError("Permission denied, ask the project owner to grant you access")
wandb.errors.CommError: Permission denied, ask the project owner to grant you access

During handling of the above exception, another exception occurred:

Traceback (most recent call last):
  File "D:\anaconda\envs\myprompt\lib\site-packages\wandb\sdk\internal\internal_util.py", line 52, in run
    self._run()
  File "D:\anaconda\envs\myprompt\lib\site-packages\wandb\sdk\internal\internal_util.py", line 102, in _run
    self._process(record)
  File "D:\anaconda\envs\myprompt\lib\site-packages\wandb\sdk\internal\internal.py", line 291, in _process
    self._sm.send(record)
  File "D:\anaconda\envs\myprompt\lib\site-packages\wandb\sdk\internal\sender.py", line 236, in send
    send_handler(record)
  File "D:\anaconda\envs\myprompt\lib\site-packages\wandb\sdk\internal\sender.py", line 687, in send_run
    self._init_run(run, config_value_dict)
  File "D:\anaconda\envs\myprompt\lib\site-packages\wandb\sdk\internal\sender.py", line 725, in _init_run
    commit=run.git.last_commit or None,
  File "D:\anaconda\envs\myprompt\lib\site-packages\wandb\apis\normalize.py", line 62, in wrapper
    six.reraise(CommError, CommError(message, err), sys.exc_info()[2])
  File "D:\anaconda\envs\myprompt\lib\site-packages\six.py", line 718, in reraise
    raise value.with_traceback(tb)
  File "D:\anaconda\envs\myprompt\lib\site-packages\wandb\apis\normalize.py", line 24, in wrapper
    return func(*args, **kwargs)
  File "D:\anaconda\envs\myprompt\lib\site-packages\wandb\sdk\internal\internal_api.py", line 1298, in upsert_run
    response = self.gql(mutation, variable_values=variable_values, **kwargs)
  File "D:\anaconda\envs\myprompt\lib\site-packages\wandb\sdk\lib\retry.py", line 118, in __call__
    if not check_retry_fn(e):
  File "D:\anaconda\envs\myprompt\lib\site-packages\wandb\util.py", line 821, in no_retry_auth
    raise CommError("Permission denied, ask the project owner to grant you access")
wandb.errors.CommError: Permission denied, ask the project owner to grant you access
2022-01-05 20:59:19,865 INFO    MainThread:33796 [internal.py:handle_exit():77] Internal process exited
